<?xml version="1.0"?>
<robot name="mrm" xmlns:xacro="http://www.ros.org/wiki/xacro">
    <link name="base_link">
        <visual>
            <origin rpy="0 0 0" xyz="0 0 0.02262"/>
            <geometry>
                <box size="0.197 0.197 0.04524"/>
            </geometry>
        </visual>
    </link>
    
    <joint name="base_link__link_01" type="revolute">
        <axis xyz="0 0 1" />
        <limit effort="1000.0" lower="-3.14" upper="3.14" velocity="0.5" />
        <origin rpy="0 0 0" xyz="0 0 0.203"/>
        <parent link="base_link"/>
        <child link="link1"/>
    </joint>
    
    <link name="link1">
        <visual>
            <origin rpy="0 0 0" xyz="0 0 -0.07888"/>
            <geometry>
                <cylinder radius="0.0985" length="0.15776"/>
            </geometry>
        </visual>

        <visual>
            <origin rpy="1.57079632679 0 0" xyz="0 0.07 0"/>
            <geometry>
                <cylinder radius="0.02" length="0.130"/>
            </geometry>
        </visual>
    </link>

    <joint name="link_01__link_02" type="revolute">
        <axis xyz="1 0 0" />
        <limit effort="1000.0" lower="-3.14" upper="3.14" velocity="0.5" />
        <origin rpy="0 0 0" xyz="0 0.1295 0"/>
        <parent link="link1"/>
        <child link="link2"/>
    </joint>

    <link name="link2">
        <visual>
            <origin rpy="3.14 0 0" xyz="0 0 0.4375"/>
            <geometry>
                <cylinder radius="0.0889" length="0.875"/>
            </geometry>
        </visual>
    </link>
    <joint name="link_02__link_03" type="revolute">
        <axis xyz="1 0 0" />
        <limit effort="1000.0" lower="-3.14" upper="3.14" velocity="0.5" />
        <origin rpy="0 0 0" xyz="0 0 0.875"/>
        <parent link="link2"/>
        <child link="link3"/>
    </joint>

    <link name="link3">
        <visual>
            <origin rpy="1.57079632679 0 0" xyz="0 0.15 0"/>
            <geometry>
                <cylinder radius="0.0889" length="0.3"/>
            </geometry>
        </visual>
        <visual>
            <origin rpy="0 0 0" xyz="0 0.1278 -0.274"/>
            <geometry>
                <cylinder radius="0.05" length="0.548"/>
            </geometry>
        </visual>
    </link>

    <joint name="link_03__link_04" type="revolute">
        <axis xyz="1 0 0" />
        <limit effort="1000.0" lower="-3.14" upper="3.14" velocity="0.5" />
        <origin rpy="0 0 0" xyz="0 0.1389 -0.548"/>
        <parent link="link3"/>
        <child link="link4"/>
    </joint>

    <link name="link4">
        <visual>
            <origin rpy="0 0 0" xyz="0 0 -0.0605"/>
            <geometry>
                <cylinder radius="0.02" length="0.121"/>
            </geometry>
        </visual>
    </link>

    <joint name="link_04__link_05" type="revolute">
        <axis xyz="0 1 0" />
        <limit effort="1000.0" lower="-3.14" upper="3.14" velocity="0.5" />
        <origin rpy="0 0 0" xyz="0 0 -0.121"/>
        <parent link="link4"/>
        <child link="link5"/>
    </joint>

    <link name="link5">
        <visual>
            <origin rpy="0 0 0" xyz="0 0 -0.05"/>
            <geometry>
                <cylinder radius="0.01" length="0.1"/>
            </geometry>
        </visual>
    </link>
</robot>