<?xml version="1.0"?>
<robot name="mrm" xmlns:xacro="http://www.ros.org/wiki/xacro">
    <link name="base_link">
        <visual>
            <origin rpy="0 0 0" xyz="0 0 0"/>
            <geometry>
                <box size="1 1 1"/>
            </geometry>
        </visual>
    </link>
    
    <joint name="base_link__link_01" type="revolute">
        <axis xyz="0 0 1" />
        <limit effort="1000.0" lower="-3.14" upper="3.14" velocity="0.5" />
        <origin rpy="0 0 0" xyz="0 0 0.5"/>
        <parent link="base_link"/>
        <child link="link1"/>
    </joint>
    
    <link name="link1">
        <visual>
            <origin rpy="0 0 0" xyz="0 0 0.2"/>
            <geometry>
                <cylinder radius="0.35" length="0.4"/>
            </geometry>
        </visual>

        <visual>
            <origin rpy="1.8 0 0" xyz="0 0.5 0.3"/>
            <geometry>
                <cylinder radius="0.1" length="1"/>
            </geometry>
        </visual>
    </link>

    <joint name="link_01__link_02" type="revolute">
        <axis xyz="1 0 0" />
        <limit effort="1000.0" lower="-3.14" upper="3.14" velocity="0.5" />
        <origin rpy="0 0 0" xyz="0 0.9 0.5"/>
        <parent link="link1"/>
        <child link="link2"/>
    </joint>

    <link name="link2">
        <visual>
            <origin rpy="3.14 0 0" xyz="0 0 0.5 "/>
            <geometry>
                <cylinder radius="0.1" length="1"/>
            </geometry>
        </visual>
    </link>

    <joint name="link_02__link_03" type="revolute">
        <axis xyz="1 0 0" />
        <limit effort="1000.0" lower="-3.14" upper="3.14" velocity="0.5" />
        <origin rpy="0 0 0" xyz="0 0 1"/>
        <parent link="link2"/>
        <child link="link3"/>
    </joint>

    <link name="link3">
        <visual>
            <origin rpy="-2.6 0 0" xyz="0 0.35 -0.35"/>
            <geometry>
                <cylinder radius="0.1" length="1"/>
            </geometry>
        </visual>
    </link>

    <joint name="link_03__link_04" type="revolute">
        <axis xyz="1 0 0" />
        <limit effort="1000.0" lower="-3.14" upper="3.14" velocity="0.5" />
        <origin rpy="0 0 0" xyz="0 0.685 -0.8"/>
        <parent link="link3"/>
        <child link="link4"/>
    </joint>

    <link name="link4">
        <visual>
            <origin rpy="1.571 0 0" xyz="0 0.25 0"/>
            <geometry>
                <cylinder radius="0.1" length="0.5"/>
            </geometry>
        </visual>
    </link>

    <joint name="link_04__link_05" type="revolute">
        <axis xyz="0 0 1" />
        <limit effort="1000.0" lower="-3.14" upper="3.14" velocity="0.5" />
        <origin rpy="0 0 0" xyz="0 0.6 0"/>
        <parent link="link4"/>
        <child link="link5"/>
    </joint>

    <link name="link5">
        <visual>
            <origin rpy="1.571 0 0" xyz="0 0.25 0"/>
            <geometry>
                <cylinder radius="0.1" length="0.5"/>
            </geometry>
        </visual>
    </link>
</robot>